Workbook

Sheet Readme
A1: Print each scenrio sheet making sure that the city column is hidden, add in a different channel per scenerio. On the Calcu sheet, type the name in and if it matches, the team will get a point.

Sheet Calcul
B1: Order | D1: Scenerio 1 | E1: Scenerio 2 | F1: Scenerio 3 | G1: Scenerio 4 | H1: Scenerio 5 | I1: Scenerio 1 Points
A3: ZTA | C3: =SUM(I3:AA3) -> 0 | I3: =IF(ISBLANK(D3),"",IF(D3=I$8,1,-1)) | J3: =IF(ISBLANK(E3),"",IF(E3=J$8,1,-1)) | K3: =IF(ISBLANK(F3),"",IF(F3=K$8,1,-1)) | L3: =IF(ISBLANK(G3),"",IF(G3=L$8,1,-1)) | M3: =IF(ISBLANK(H3),"",IF(H3=M$8,1,-1))
A4: ZTB | C4: =SUM(I4:AA4) -> 0 | I4: =IF(ISBLANK(D4),"",IF(D4=I$8,1,-1)) | J4: =IF(ISBLANK(E4),"",IF(E4=J$8,1,-1)) | K4: =IF(ISBLANK(F4),"",IF(F4=K$8,1,-1)) | L4: =IF(ISBLANK(G4),"",IF(G4=L$8,1,-1)) | M4: =IF(ISBLANK(H4),"",IF(H4=M$8,1,-1))
A5: ZTC | C5: =SUM(I5:AA5) -> 0 | I5: =IF(ISBLANK(D5),"",IF(D5=I$8,1,-1)) | J5: =IF(ISBLANK(E5),"",IF(E5=J$8,1,-1)) | K5: =IF(ISBLANK(F5),"",IF(F5=K$8,1,-1)) | L5: =IF(ISBLANK(G5),"",IF(G5=L$8,1,-1)) | M5: =IF(ISBLANK(H5),"",IF(H5=M$8,1,-1))
A6: ZTD | C6: =SUM(I6:AA6) -> 0 | I6: =IF(ISBLANK(D6),"",IF(D6=I$8,1,-1)) | J6: =IF(ISBLANK(E6),"",IF(E6=J$8,1,-1)) | K6: =IF(ISBLANK(F6),"",IF(F6=K$8,1,-1)) | L6: =IF(ISBLANK(G6),"",IF(G6=L$8,1,-1)) | M6: =IF(ISBLANK(H6),"",IF(H6=M$8,1,-1))
A7: ZTE | C7: =SUM(I7:AA7) -> 0 | I7: =IF(ISBLANK(D7),"",IF(D7=I$8,1,-1)) | J7: =IF(ISBLANK(E7),"",IF(E7=J$8,1,-1)) | K7: =IF(ISBLANK(F7),"",IF(F7=K$8,1,-1)) | L7: =IF(ISBLANK(G7),"",IF(G7=L$8,1,-1)) | M7: =IF(ISBLANK(H7),"",IF(H7=M$8,1,-1))
I8: Beaver Falls | J8: Bradford | K8: Washington | L8: Altoona | M8: Duquesne
A11: Channel 3: | D11: 462.61250Mhz
A12: Channel 4: | D12: 462.66250Mhz
A13: Channel 5: | D13: 462.63750Mhz
A14: Channel 8: | D14: 467.56250Mhz

Sheet Scenario 1
G1: Scenario 1 | I1: Channel:
A2: People | C2: Beaver Falls | D2: Location 1 | E2: Location 2 | F2: Location 3 | G2: Location 4 | H2: Location 5 | I2: Location 6 | J2: Location 7 | K2: Location 8 | L2: Location 9 | M2: Location 10
A3: a | C3: =COUNTIF(D3:M3, "Beaver Falls") -> 0 | D3: =VLOOKUP('Formula Workbook'!W2,Cities!$A:$B,2,FALSE) -> Hazleton | E3: =VLOOKUP('Formula Workbook'!X2,Cities!$A:$B,2,FALSE) -> Pittsburgh | F3: =VLOOKUP('Formula Workbook'!Y2,Cities!$A:$B,2,FALSE) -> Altoona | G3: =VLOOKUP('Formula Workbook'!Z2,Cities!$A:$B,2,FALSE) -> Bethlehem | H3: =VLOOKUP('Formula Workbook'!AA2,Cities!$A:$B,2,FALSE) -> Duquesne | I3: =VLOOKUP('Formula Workbook'!AB2,Cities!$A:$B,2,FALSE) -> Hazleton | J3: =VLOOKUP('Formula Workbook'!AC2,Cities!$A:$B,2,FALSE) -> Chester | K3: =VLOOKUP('Formula Workbook'!AD2,Cities!$A:$B,2,FALSE) -> Butler | ... M3: =VLOOKUP('Formula Workbook'!AF2,Cities!$A:$B,2,FALSE) -> Allentown
A4: b | B4: Cholera | C4: =COUNTIF(D4:M4, "Beaver Falls") -> 1 | D4: =VLOOKUP('Formula Workbook'!W3,Cities!$A:$B,2,FALSE) -> Erie | E4: =VLOOKUP('Formula Workbook'!X3,Cities!$A:$B,2,FALSE) -> Butler | F4: =VLOOKUP('Formula Workbook'!Y3,Cities!$A:$B,2,FALSE) -> Wilkes-Barre | G4: =VLOOKUP('Formula Workbook'!Z3,Cities!$A:$B,2,FALSE) -> Harrisburg | H4: =VLOOKUP('Formula Workbook'!AA3,Cities!$A:$B,2,FALSE) -> Altoona | I4: =VLOOKUP('Formula Workbook'!AB3,Cities!$A:$B,2,FALSE) -> Erie | J4: =VLOOKUP('Formula Workbook'!AC3,Cities!$A:$B,2,FALSE) -> Reading | K4: =VLOOKUP('Formula Workbook'!AD3,Cities!$A:$B,2,FALSE) -> Jeannette | ... M4: =VLOOKUP('Formula Workbook'!AF3,Cities!$A:$B,2,FALSE) -> Beaver Falls
A5: c | B5: Cholera | C5: =COUNTIF(D5:M5, "Beaver Falls") -> 1 | D5: =VLOOKUP('Formula Workbook'!W4,Cities!$A:$B,2,FALSE) -> Franklin | E5: =VLOOKUP('Formula Workbook'!X4,Cities!$A:$B,2,FALSE) -> Chester | F5: =VLOOKUP('Formula Workbook'!Y4,Cities!$A:$B,2,FALSE) -> Beaver Falls | G5: =VLOOKUP('Formula Workbook'!Z4,Cities!$A:$B,2,FALSE) -> Franklin | H5: =VLOOKUP('Formula Workbook'!AA4,Cities!$A:$B,2,FALSE) -> Allentown | I5: =VLOOKUP('Formula Workbook'!AB4,Cities!$A:$B,2,FALSE) -> Hazleton | J5: =VLOOKUP('Formula Workbook'!AC4,Cities!$A:$B,2,FALSE) -> Franklin | K5: =VLOOKUP('Formula Workbook'!AD4,Cities!$A:$B,2,FALSE) -> Harrisburg | ... M5: =VLOOKUP('Formula Workbook'!AF4,Cities!$A:$B,2,FALSE) -> Corry
A6: d | B6: Cholera | C6: =COUNTIF(D6:M6, "Beaver Falls") -> 1 | D6: =VLOOKUP('Formula Workbook'!W5,Cities!$A:$B,2,FALSE) -> Aliquippa | E6: =VLOOKUP('Formula Workbook'!X5,Cities!$A:$B,2,FALSE) -> Harrisburg | F6: =VLOOKUP('Formula Workbook'!Y5,Cities!$A:$B,2,FALSE) -> Beaver Falls | G6: =VLOOKUP('Formula Workbook'!Z5,Cities!$A:$B,2,FALSE) -> DuBois | H6: =VLOOKUP('Formula Workbook'!AA5,Cities!$A:$B,2,FALSE) -> Bethlehem | I6: =VLOOKUP('Formula Workbook'!AB5,Cities!$A:$B,2,FALSE) -> Bethlehem | J6: =VLOOKUP('Formula Workbook'!AC5,Cities!$A:$B,2,FALSE) -> Philadelphia | K6: =VLOOKUP('Formula Workbook'!AD5,Cities!$A:$B,2,FALSE) -> Butler | ... M6: =VLOOKUP('Formula Workbook'!AF5,Cities!$A:$B,2,FALSE) -> Wilkes-Barre
A7: e | B7: Cholera | C7: =COUNTIF(D7:M7, "Beaver Falls") -> 1 | D7: =VLOOKUP('Formula Workbook'!W6,Cities!$A:$B,2,FALSE) -> Wilkes-Barre | E7: =VLOOKUP('Formula Workbook'!X6,Cities!$A:$B,2,FALSE) -> Bethlehem | F7: =VLOOKUP('Formula Workbook'!Y6,Cities!$A:$B,2,FALSE) -> Aliquippa | G7: =VLOOKUP('Formula Workbook'!Z6,Cities!$A:$B,2,FALSE) -> Beaver Falls | H7: =VLOOKUP('Formula Workbook'!AA6,Cities!$A:$B,2,FALSE) -> DuBois | I7: =VLOOKUP('Formula Workbook'!AB6,Cities!$A:$B,2,FALSE) -> Washington | J7: =VLOOKUP('Formula Workbook'!AC6,Cities!$A:$B,2,FALSE) -> Erie | K7: =VLOOKUP('Formula Workbook'!AD6,Cities!$A:$B,2,FALSE) -> Reading | ... M7: =VLOOKUP('Formula Workbook'!AF6,Cities!$A:$B,2,FALSE) -> Reading
A8: f | C8: =COUNTIF(D8:M8, "Beaver Falls") -> 0 | D8: =VLOOKUP('Formula Workbook'!W7,Cities!$A:$B,2,FALSE) -> Butler | E8: =VLOOKUP('Formula Workbook'!X7,Cities!$A:$B,2,FALSE) -> Jeannette | F8: =VLOOKUP('Formula Workbook'!Y7,Cities!$A:$B,2,FALSE) -> Easton | G8: =VLOOKUP('Formula Workbook'!Z7,Cities!$A:$B,2,FALSE) -> Bethlehem | H8: =VLOOKUP('Formula Workbook'!AA7,Cities!$A:$B,2,FALSE) -> Reading | I8: =VLOOKUP('Formula Workbook'!AB7,Cities!$A:$B,2,FALSE) -> Washington | J8: =VLOOKUP('Formula Workbook'!AC7,Cities!$A:$B,2,FALSE) -> Harrisburg | K8: =VLOOKUP('Formula Workbook'!AD7,Cities!$A:$B,2,FALSE) -> Franklin | ... M8: =VLOOKUP('Formula Workbook'!AF7,Cities!$A:$B,2,FALSE) -> Corry
A9: g | C9: =COUNTIF(D9:M9, "Beaver Falls") -> 0 | D9: =VLOOKUP('Formula Workbook'!W8,Cities!$A:$B,2,FALSE) -> Erie | E9: =VLOOKUP('Formula Workbook'!X8,Cities!$A:$B,2,FALSE) -> DuBois | F9: =VLOOKUP('Formula Workbook'!Y8,Cities!$A:$B,2,FALSE) -> Allentown | G9: =VLOOKUP('Formula Workbook'!Z8,Cities!$A:$B,2,FALSE) -> Harrisburg | H9: =VLOOKUP('Formula Workbook'!AA8,Cities!$A:$B,2,FALSE) -> Wilkes-Barre | I9: =VLOOKUP('Formula Workbook'!AB8,Cities!$A:$B,2,FALSE) -> Clairton | J9: =VLOOKUP('Formula Workbook'!AC8,Cities!$A:$B,2,FALSE) -> Connellsville | K9: =VLOOKUP('Formula Workbook'!AD8,Cities!$A:$B,2,FALSE) -> Easton | ... M9: =VLOOKUP('Formula Workbook'!AF8,Cities!$A:$B,2,FALSE) -> Connellsville
A10: h | C10: =COUNTIF(D10:M10, "Beaver Falls") -> 0 | D10: =VLOOKUP('Formula Workbook'!W9,Cities!$A:$B,2,FALSE) -> Washington | E10: =VLOOKUP('Formula Workbook'!X9,Cities!$A:$B,2,FALSE) -> Greensburg | F10: =VLOOKUP('Formula Workbook'!Y9,Cities!$A:$B,2,FALSE) -> Hazleton | G10: =VLOOKUP('Formula Workbook'!Z9,Cities!$A:$B,2,FALSE) -> Reading | H10: =VLOOKUP('Formula Workbook'!AA9,Cities!$A:$B,2,FALSE) -> Chester | I10: =VLOOKUP('Formula Workbook'!AB9,Cities!$A:$B,2,FALSE) -> Harrisburg | J10: =VLOOKUP('Formula Workbook'!AC9,Cities!$A:$B,2,FALSE) -> Franklin | K10: =VLOOKUP('Formula Workbook'!AD9,Cities!$A:$B,2,FALSE) -> Hazleton | ... M10: =VLOOKUP('Formula Workbook'!AF9,Cities!$A:$B,2,FALSE) -> Harrisburg
A11: i | B11: Cholera | C11: =COUNTIF(D11:M11, "Beaver Falls") -> 1 | D11: =VLOOKUP('Formula Workbook'!W10,Cities!$A:$B,2,FALSE) -> Hermitage | E11: =VLOOKUP('Formula Workbook'!X10,Cities!$A:$B,2,FALSE) -> Hazleton | F11: =VLOOKUP('Formula Workbook'!Y10,Cities!$A:$B,2,FALSE) -> Bethlehem | G11: =VLOOKUP('Formula Workbook'!Z10,Cities!$A:$B,2,FALSE) -> Harrisburg | H11: =VLOOKUP('Formula Workbook'!AA10,Cities!$A:$B,2,FALSE) -> Clairton | I11: =VLOOKUP('Formula Workbook'!AB10,Cities!$A:$B,2,FALSE) -> Beaver Falls | J11: =VLOOKUP('Formula Workbook'!AC10,Cities!$A:$B,2,FALSE) -> Washington | K11: =VLOOKUP('Formula Workbook'!AD10,Cities!$A:$B,2,FALSE) -> Washington | ... M11: =VLOOKUP('Formula Workbook'!AF10,Cities!$A:$B,2,FALSE) -> Aliquippa
A12: j | C12: =COUNTIF(D12:M12, "Beaver Falls") -> 0 | D12: =VLOOKUP('Formula Workbook'!W11,Cities!$A:$B,2,FALSE) -> Greensburg | E12: =VLOOKUP('Formula Workbook'!X11,Cities!$A:$B,2,FALSE) -> Clairton | F12: =VLOOKUP('Formula Workbook'!Y11,Cities!$A:$B,2,FALSE) -> Erie | G12: =VLOOKUP('Formula Workbook'!Z11,Cities!$A:$B,2,FALSE) -> Harrisburg | H12: =VLOOKUP('Formula Workbook'!AA11,Cities!$A:$B,2,FALSE) -> Connellsville | I12: =VLOOKUP('Formula Workbook'!AB11,Cities!$A:$B,2,FALSE) -> Chester | J12: =VLOOKUP('Formula Workbook'!AC11,Cities!$A:$B,2,FALSE) -> Easton | K12: =VLOOKUP('Formula Workbook'!AD11,Cities!$A:$B,2,FALSE) -> Pittsburgh | ... M12: =VLOOKUP('Formula Workbook'!AF11,Cities!$A:$B,2,FALSE) -> Bethlehem
A13: k | C13: =COUNTIF(D13:M13, "Beaver Falls") -> 0 | D13: =VLOOKUP('Formula Workbook'!W12,Cities!$A:$B,2,FALSE) -> Washington | E13: =VLOOKUP('Formula Workbook'!X12,Cities!$A:$B,2,FALSE) -> Connellsville | F13: =VLOOKUP('Formula Workbook'!Y12,Cities!$A:$B,2,FALSE) -> Aliquippa | G13: =VLOOKUP('Formula Workbook'!Z12,Cities!$A:$B,2,FALSE) -> Duquesne | H13: =VLOOKUP('Formula Workbook'!AA12,Cities!$A:$B,2,FALSE) -> Aliquippa | I13: =VLOOKUP('Formula Workbook'!AB12,Cities!$A:$B,2,FALSE) -> Easton | J13: =VLOOKUP('Formula Workbook'!AC12,Cities!$A:$B,2,FALSE) -> Bradford | K13: =VLOOKUP('Formula Workbook'!AD12,Cities!$A:$B,2,FALSE) -> Hermitage | ... M13: =VLOOKUP('Formula Workbook'!AF12,Cities!$A:$B,2,FALSE) -> Aliquippa
A14: l | B14: Cholera | C14: =COUNTIF(D14:M14, "Beaver Falls") -> 3 | D14: =VLOOKUP('Formula Workbook'!W13,Cities!$A:$B,2,FALSE) -> Corry | E14: =VLOOKUP('Formula Workbook'!X13,Cities!$A:$B,2,FALSE) -> Bethlehem | F14: =VLOOKUP('Formula Workbook'!Y13,Cities!$A:$B,2,FALSE) -> Hermitage | G14: =VLOOKUP('Formula Workbook'!Z13,Cities!$A:$B,2,FALSE) -> Aliquippa | H14: =VLOOKUP('Formula Workbook'!AA13,Cities!$A:$B,2,FALSE) -> Wilkes-Barre | I14: =VLOOKUP('Formula Workbook'!AB13,Cities!$A:$B,2,FALSE) -> Aliquippa | J14: =VLOOKUP('Formula Workbook'!AC13,Cities!$A:$B,2,FALSE) -> Bradford | K14: =VLOOKUP('Formula Workbook'!AD13,Cities!$A:$B,2,FALSE) -> Beaver Falls | ... M14: =VLOOKUP('Formula Workbook'!AF13,Cities!$A:$B,2,FALSE) -> Beaver Falls
A15: m | C15: =COUNTIF(D15:M15, "Beaver Falls") -> 0 | D15: =VLOOKUP('Formula Workbook'!W14,Cities!$A:$B,2,FALSE) -> Washington | E15: =VLOOKUP('Formula Workbook'!X14,Cities!$A:$B,2,FALSE) -> Duquesne | F15: =VLOOKUP('Formula Workbook'!Y14,Cities!$A:$B,2,FALSE) -> Altoona | G15: =VLOOKUP('Formula Workbook'!Z14,Cities!$A:$B,2,FALSE) -> Hazleton | H15: =VLOOKUP('Formula Workbook'!AA14,Cities!$A:$B,2,FALSE) -> Connellsville | I15: =VLOOKUP('Formula Workbook'!AB14,Cities!$A:$B,2,FALSE) -> Hermitage | J15: =VLOOKUP('Formula Workbook'!AC14,Cities!$A:$B,2,FALSE) -> Altoona | K15: =VLOOKUP('Formula Workbook'!AD14,Cities!$A:$B,2,FALSE) -> Pittsburgh | ... M15: =VLOOKUP('Formula Workbook'!AF14,Cities!$A:$B,2,FALSE) -> Corry
A16: n | C16: =COUNTIF(D16:M16, "Beaver Falls") -> 0 | D16: =VLOOKUP('Formula Workbook'!W15,Cities!$A:$B,2,FALSE) -> Connellsville | E16: =VLOOKUP('Formula Workbook'!X15,Cities!$A:$B,2,FALSE) -> Franklin | F16: =VLOOKUP('Formula Workbook'!Y15,Cities!$A:$B,2,FALSE) -> Allentown | G16: =VLOOKUP('Formula Workbook'!Z15,Cities!$A:$B,2,FALSE) -> Corry | H16: =VLOOKUP('Formula Workbook'!AA15,Cities!$A:$B,2,FALSE) -> Pittsburgh | I16: =VLOOKUP('Formula Workbook'!AB15,Cities!$A:$B,2,FALSE) -> Clairton | J16: =VLOOKUP('Formula Workbook'!AC15,Cities!$A:$B,2,FALSE) -> Hazleton | K16: =VLOOKUP('Formula Workbook'!AD15,Cities!$A:$B,2,FALSE) -> Philadelphia | ... M16: =VLOOKUP('Formula Workbook'!AF15,Cities!$A:$B,2,FALSE) -> Wilkes-Barre
A17: o | C17: =COUNTIF(D17:M17, "Beaver Falls") -> 0 | D17: =VLOOKUP('Formula Workbook'!W16,Cities!$A:$B,2,FALSE) -> Philadelphia | E17: =VLOOKUP('Formula Workbook'!X16,Cities!$A:$B,2,FALSE) -> Easton | F17: =VLOOKUP('Formula Workbook'!Y16,Cities!$A:$B,2,FALSE) -> Easton | G17: =VLOOKUP('Formula Workbook'!Z16,Cities!$A:$B,2,FALSE) -> Jeannette | H17: =VLOOKUP('Formula Workbook'!AA16,Cities!$A:$B,2,FALSE) -> Easton | I17: =VLOOKUP('Formula Workbook'!AB16,Cities!$A:$B,2,FALSE) -> Altoona | J17: =VLOOKUP('Formula Workbook'!AC16,Cities!$A:$B,2,FALSE) -> Washington | K17: =VLOOKUP('Formula Workbook'!AD16,Cities!$A:$B,2,FALSE) -> Erie | ... M17: =VLOOKUP('Formula Workbook'!AF16,Cities!$A:$B,2,FALSE) -> Hazleton
A18: p | C18: =COUNTIF(D18:M18, "Beaver Falls") -> 0 | D18: =VLOOKUP('Formula Workbook'!W17,Cities!$A:$B,2,FALSE) -> Butler | E18: =VLOOKUP('Formula Workbook'!X17,Cities!$A:$B,2,FALSE) -> Erie | F18: =VLOOKUP('Formula Workbook'!Y17,Cities!$A:$B,2,FALSE) -> Bradford | G18: =VLOOKUP('Formula Workbook'!Z17,Cities!$A:$B,2,FALSE) -> Connellsville | H18: =VLOOKUP('Formula Workbook'!AA17,Cities!$A:$B,2,FALSE) -> Franklin | I18: =VLOOKUP('Formula Workbook'!AB17,Cities!$A:$B,2,FALSE) -> Duquesne | J18: =VLOOKUP('Formula Workbook'!AC17,Cities!$A:$B,2,FALSE) -> Duquesne | K18: =VLOOKUP('Formula Workbook'!AD17,Cities!$A:$B,2,FALSE) -> Allentown | ... M18: =VLOOKUP('Formula Workbook'!AF17,Cities!$A:$B,2,FALSE) -> Corry
A19: q | B19: Cholera | C19: =COUNTIF(D19:M19, "Beaver Falls") -> 2 | D19: =VLOOKUP('Formula Workbook'!W18,Cities!$A:$B,2,FALSE) -> Greensburg | E19: =VLOOKUP('Formula Workbook'!X18,Cities!$A:$B,2,FALSE) -> Clairton | F19: =VLOOKUP('Formula Workbook'!Y18,Cities!$A:$B,2,FALSE) -> Hermitage | G19: =VLOOKUP('Formula Workbook'!Z18,Cities!$A:$B,2,FALSE) -> Duquesne | H19: =VLOOKUP('Formula Workbook'!AA18,Cities!$A:$B,2,FALSE) -> Beaver Falls | I19: =VLOOKUP('Formula Workbook'!AB18,Cities!$A:$B,2,FALSE) -> Chester | J19: =VLOOKUP('Formula Workbook'!AC18,Cities!$A:$B,2,FALSE) -> Hazleton | K19: =VLOOKUP('Formula Workbook'!AD18,Cities!$A:$B,2,FALSE) -> Clairton | ... M19: =VLOOKUP('Formula Workbook'!AF18,Cities!$A:$B,2,FALSE) -> Beaver Falls
A20: r | C20: =COUNTIF(D20:M20, "Beaver Falls") -> 0 | D20: =VLOOKUP('Formula Workbook'!W19,Cities!$A:$B,2,FALSE) -> Greensburg | E20: =VLOOKUP('Formula Workbook'!X19,Cities!$A:$B,2,FALSE) -> Bradford | F20: =VLOOKUP('Formula Workbook'!Y19,Cities!$A:$B,2,FALSE) -> Altoona | G20: =VLOOKUP('Formula Workbook'!Z19,Cities!$A:$B,2,FALSE) -> Corry | H20: =VLOOKUP('Formula Workbook'!AA19,Cities!$A:$B,2,FALSE) -> Easton | I20: =VLOOKUP('Formula Workbook'!AB19,Cities!$A:$B,2,FALSE) -> Greensburg | J20: =VLOOKUP('Formula Workbook'!AC19,Cities!$A:$B,2,FALSE) -> Hermitage | K20: =VLOOKUP('Formula Workbook'!AD19,Cities!$A:$B,2,FALSE) -> Hermitage | ... M20: =VLOOKUP('Formula Workbook'!AF19,Cities!$A:$B,2,FALSE) -> Washington
A21: s | B21: Cholera | C21: =COUNTIF(D21:M21, "Beaver Falls") -> 1 | D21: =VLOOKUP('Formula Workbook'!W20,Cities!$A:$B,2,FALSE) -> Corry | E21: =VLOOKUP('Formula Workbook'!X20,Cities!$A:$B,2,FALSE) -> Washington | F21: =VLOOKUP('Formula Workbook'!Y20,Cities!$A:$B,2,FALSE) -> Beaver Falls | G21: =VLOOKUP('Formula Workbook'!Z20,Cities!$A:$B,2,FALSE) -> Hermitage | H21: =VLOOKUP('Formula Workbook'!AA20,Cities!$A:$B,2,FALSE) -> Jeannette | I21: =VLOOKUP('Formula Workbook'!AB20,Cities!$A:$B,2,FALSE) -> Pittsburgh | J21: =VLOOKUP('Formula Workbook'!AC20,Cities!$A:$B,2,FALSE) -> Hermitage | K21: =VLOOKUP('Formula Workbook'!AD20,Cities!$A:$B,2,FALSE) -> Wilkes-Barre | ... M21: =VLOOKUP('Formula Workbook'!AF20,Cities!$A:$B,2,FALSE) -> Reading
A22: t | C22: =COUNTIF(D22:M22, "Beaver Falls") -> 0 | D22: =VLOOKUP('Formula Workbook'!W21,Cities!$A:$B,2,FALSE) -> Connellsville | E22: =VLOOKUP('Formula Workbook'!X21,Cities!$A:$B,2,FALSE) -> Pittsburgh | F22: =VLOOKUP('Formula Workbook'!Y21,Cities!$A:$B,2,FALSE) -> Harrisburg | G22: =VLOOKUP('Formula Workbook'!Z21,Cities!$A:$B,2,FALSE) -> Erie | H22: =VLOOKUP('Formula Workbook'!AA21,Cities!$A:$B,2,FALSE) -> Franklin | I22: =VLOOKUP('Formula Workbook'!AB21,Cities!$A:$B,2,FALSE) -> Harrisburg | J22: =VLOOKUP('Formula Workbook'!AC21,Cities!$A:$B,2,FALSE) -> Bradford | K22: =VLOOKUP('Formula Workbook'!AD21,Cities!$A:$B,2,FALSE) -> Pittsburgh | ... M22: =VLOOKUP('Formula Workbook'!AF21,Cities!$A:$B,2,FALSE) -> Duquesne
A23: u | B23: Cholera | C23: =COUNTIF(D23:M23, "Beaver Falls") -> 1 | D23: =VLOOKUP('Formula Workbook'!W22,Cities!$A:$B,2,FALSE) -> Bethlehem | E23: =VLOOKUP('Formula Workbook'!X22,Cities!$A:$B,2,FALSE) -> Washington | F23: =VLOOKUP('Formula Workbook'!Y22,Cities!$A:$B,2,FALSE) -> Chester | G23: =VLOOKUP('Formula Workbook'!Z22,Cities!$A:$B,2,FALSE) -> DuBois | H23: =VLOOKUP('Formula Workbook'!AA22,Cities!$A:$B,2,FALSE) -> Bethlehem | I23: =VLOOKUP('Formula Workbook'!AB22,Cities!$A:$B,2,FALSE) -> Beaver Falls | J23: =VLOOKUP('Formula Workbook'!AC22,Cities!$A:$B,2,FALSE) -> Altoona | K23: =VLOOKUP('Formula Workbook'!AD22,Cities!$A:$B,2,FALSE) -> Hazleton | ... M23: =VLOOKUP('Formula Workbook'!AF22,Cities!$A:$B,2,FALSE) -> Wilkes-Barre
A24: v | B24: Cholera | C24: =COUNTIF(D24:M24, "Beaver Falls") -> 1 | D24: =VLOOKUP('Formula Workbook'!W23,Cities!$A:$B,2,FALSE) -> Beaver Falls | E24: =VLOOKUP('Formula Workbook'!X23,Cities!$A:$B,2,FALSE) -> Allentown | F24: =VLOOKUP('Formula Workbook'!Y23,Cities!$A:$B,2,FALSE) -> Reading | G24: =VLOOKUP('Formula Workbook'!Z23,Cities!$A:$B,2,FALSE) -> Bethlehem | H24: =VLOOKUP('Formula Workbook'!AA23,Cities!$A:$B,2,FALSE) -> Philadelphia | I24: =VLOOKUP('Formula Workbook'!AB23,Cities!$A:$B,2,FALSE) -> Wilkes-Barre | J24: =VLOOKUP('Formula Workbook'!AC23,Cities!$A:$B,2,FALSE) -> Philadelphia | K24: =VLOOKUP('Formula Workbook'!AD23,Cities!$A:$B,2,FALSE) -> Easton | ... M24: =VLOOKUP('Formula Workbook'!AF23,Cities!$A:$B,2,FALSE) -> Altoona
A25: w | C25: =COUNTIF(D25:M25, "Beaver Falls") -> 0 | D25: =VLOOKUP('Formula Workbook'!W24,Cities!$A:$B,2,FALSE) -> Altoona | E25: =VLOOKUP('Formula Workbook'!X24,Cities!$A:$B,2,FALSE) -> Harrisburg | F25: =VLOOKUP('Formula Workbook'!Y24,Cities!$A:$B,2,FALSE) -> Altoona | G25: =VLOOKUP('Formula Workbook'!Z24,Cities!$A:$B,2,FALSE) -> Jeannette | H25: =VLOOKUP('Formula Workbook'!AA24,Cities!$A:$B,2,FALSE) -> Corry | I25: =VLOOKUP('Formula Workbook'!AB24,Cities!$A:$B,2,FALSE) -> Allentown | J25: =VLOOKUP('Formula Workbook'!AC24,Cities!$A:$B,2,FALSE) -> Clairton | K25: =VLOOKUP('Formula Workbook'!AD24,Cities!$A:$B,2,FALSE) -> Harrisburg | ... M25: =VLOOKUP('Formula Workbook'!AF24,Cities!$A:$B,2,FALSE) -> Easton
A26: x | B26: Cholera | C26: =COUNTIF(D26:M26, "Beaver Falls") -> 1 | D26: =VLOOKUP('Formula Workbook'!W25,Cities!$A:$B,2,FALSE) -> Beaver Falls | E26: =VLOOKUP('Formula Workbook'!X25,Cities!$A:$B,2,FALSE) -> Harrisburg | F26: =VLOOKUP('Formula Workbook'!Y25,Cities!$A:$B,2,FALSE) -> Reading | G26: =VLOOKUP('Formula Workbook'!Z25,Cities!$A:$B,2,FALSE) -> Jeannette | H26: =VLOOKUP('Formula Workbook'!AA25,Cities!$A:$B,2,FALSE) -> DuBois | I26: =VLOOKUP('Formula Workbook'!AB25,Cities!$A:$B,2,FALSE) -> Easton | J26: =VLOOKUP('Formula Workbook'!AC25,Cities!$A:$B,2,FALSE) -> Harrisburg | K26: =VLOOKUP('Formula Workbook'!AD25,Cities!$A:$B,2,FALSE) -> Chester | ... M26: =VLOOKUP('Formula Workbook'!AF25,Cities!$A:$B,2,FALSE) -> Jeannette
A27: y | B27: Cholera | C27: =COUNTIF(D27:M27, "Beaver Falls") -> 1 | D27: =VLOOKUP('Formula Workbook'!W26,Cities!$A:$B,2,FALSE) -> Wilkes-Barre | E27: =VLOOKUP('Formula Workbook'!X26,Cities!$A:$B,2,FALSE) -> Clairton | F27: =VLOOKUP('Formula Workbook'!Y26,Cities!$A:$B,2,FALSE) -> Altoona | G27: =VLOOKUP('Formula Workbook'!Z26,Cities!$A:$B,2,FALSE) -> Wilkes-Barre | H27: =VLOOKUP('Formula Workbook'!AA26,Cities!$A:$B,2,FALSE) -> Jeannette | I27: =VLOOKUP('Formula Workbook'!AB26,Cities!$A:$B,2,FALSE) -> Washington | J27: =VLOOKUP('Formula Workbook'!AC26,Cities!$A:$B,2,FALSE) -> Wilkes-Barre | K27: =VLOOKUP('Formula Workbook'!AD26,Cities!$A:$B,2,FALSE) -> Washington | ... M27: =VLOOKUP('Formula Workbook'!AF26,Cities!$A:$B,2,FALSE) -> Reading
A28: z | B28: Cholera | C28: =COUNTIF(D28:M28, "Beaver Falls") -> 2 | D28: =VLOOKUP('Formula Workbook'!W27,Cities!$A:$B,2,FALSE) -> Beaver Falls | E28: =VLOOKUP('Formula Workbook'!X27,Cities!$A:$B,2,FALSE) -> Harrisburg | F28: =VLOOKUP('Formula Workbook'!Y27,Cities!$A:$B,2,FALSE) -> Aliquippa | G28: =VLOOKUP('Formula Workbook'!Z27,Cities!$A:$B,2,FALSE) -> Allentown | H28: =VLOOKUP('Formula Workbook'!AA27,Cities!$A:$B,2,FALSE) -> Reading | I28: =VLOOKUP('Formula Workbook'!AB27,Cities!$A:$B,2,FALSE) -> Aliquippa | J28: =VLOOKUP('Formula Workbook'!AC27,Cities!$A:$B,2,FALSE) -> Reading | K28: =VLOOKUP('Formula Workbook'!AD27,Cities!$A:$B,2,FALSE) -> Beaver Falls | ... M28: =VLOOKUP('Formula Workbook'!AF27,Cities!$A:$B,2,FALSE) -> Erie

Sheet Scenario 2
G1: Scenario 2 | I1: Channel:
A2: People | B2: bradford | C2: Bradford | D2: Location 1 | E2: Location 2 | F2: Location 3 | G2: Location 4 | H2: Location 5 | I2: Location 6 | J2: Location 7 | K2: Location 8 | L2: Location 9 | M2: Location 10
A3: a | B3: Sars | C3: =COUNTIF(D3:M3,"bradford") -> 1 | D3: =VLOOKUP('Formula Workbook'!M2,Cities!$A:$B,2,FALSE) -> DuBois | E3: =VLOOKUP('Formula Workbook'!N2,Cities!$A:$B,2,FALSE) -> Corry | F3: =VLOOKUP('Formula Workbook'!O2,Cities!$A:$B,2,FALSE) -> Aliquippa | G3: =VLOOKUP('Formula Workbook'!P2,Cities!$A:$B,2,FALSE) -> Bradford | H3: =VLOOKUP('Formula Workbook'!Q2,Cities!$A:$B,2,FALSE) -> Allentown | I3: =VLOOKUP('Formula Workbook'!R2,Cities!$A:$B,2,FALSE) -> Aliquippa | J3: =VLOOKUP('Formula Workbook'!S2,Cities!$A:$B,2,FALSE) -> Aliquippa | K3: =VLOOKUP('Formula Workbook'!T2,Cities!$A:$B,2,FALSE) -> Easton | ... M3: =VLOOKUP('Formula Workbook'!V2,Cities!$A:$B,2,FALSE) -> Chester
A4: b | C4: =COUNTIF(D4:M4,"bradford") -> 0 | D4: =VLOOKUP('Formula Workbook'!M3,Cities!$A:$B,2,FALSE) -> DuBois | E4: =VLOOKUP('Formula Workbook'!N3,Cities!$A:$B,2,FALSE) -> Hermitage | F4: =VLOOKUP('Formula Workbook'!O3,Cities!$A:$B,2,FALSE) -> Hermitage | G4: =VLOOKUP('Formula Workbook'!P3,Cities!$A:$B,2,FALSE) -> Franklin | H4: =VLOOKUP('Formula Workbook'!Q3,Cities!$A:$B,2,FALSE) -> Easton | I4: =VLOOKUP('Formula Workbook'!R3,Cities!$A:$B,2,FALSE) -> Hazleton | J4: =VLOOKUP('Formula Workbook'!S3,Cities!$A:$B,2,FALSE) -> Hazleton | K4: =VLOOKUP('Formula Workbook'!T3,Cities!$A:$B,2,FALSE) -> Bethlehem | ... M4: =VLOOKUP('Formula Workbook'!V3,Cities!$A:$B,2,FALSE) -> Corry
A5: c | B5: Sars | C5: =COUNTIF(D5:M5,"bradford") -> 1 | D5: =VLOOKUP('Formula Workbook'!M4,Cities!$A:$B,2,FALSE) -> Washington | E5: =VLOOKUP('Formula Workbook'!N4,Cities!$A:$B,2,FALSE) -> Harrisburg | F5: =VLOOKUP('Formula Workbook'!O4,Cities!$A:$B,2,FALSE) -> Chester | G5: =VLOOKUP('Formula Workbook'!P4,Cities!$A:$B,2,FALSE) -> Bradford | H5: =VLOOKUP('Formula Workbook'!Q4,Cities!$A:$B,2,FALSE) -> Jeannette | I5: =VLOOKUP('Formula Workbook'!R4,Cities!$A:$B,2,FALSE) -> Hermitage | J5: =VLOOKUP('Formula Workbook'!S4,Cities!$A:$B,2,FALSE) -> Chester | K5: =VLOOKUP('Formula Workbook'!T4,Cities!$A:$B,2,FALSE) -> Franklin | ... M5: =VLOOKUP('Formula Workbook'!V4,Cities!$A:$B,2,FALSE) -> Washington
A6: d | C6: =COUNTIF(D6:M6,"bradford") -> 0 | D6: =VLOOKUP('Formula Workbook'!M5,Cities!$A:$B,2,FALSE) -> Franklin | E6: =VLOOKUP('Formula Workbook'!N5,Cities!$A:$B,2,FALSE) -> Wilkes-Barre | F6: =VLOOKUP('Formula Workbook'!O5,Cities!$A:$B,2,FALSE) -> Aliquippa | G6: =VLOOKUP('Formula Workbook'!P5,Cities!$A:$B,2,FALSE) -> Bethlehem | H6: =VLOOKUP('Formula Workbook'!Q5,Cities!$A:$B,2,FALSE) -> Reading | I6: =VLOOKUP('Formula Workbook'!R5,Cities!$A:$B,2,FALSE) -> Hermitage | J6: =VLOOKUP('Formula Workbook'!S5,Cities!$A:$B,2,FALSE) -> Butler | K6: =VLOOKUP('Formula Workbook'!T5,Cities!$A:$B,2,FALSE) -> Philadelphia | ... M6: =VLOOKUP('Formula Workbook'!V5,Cities!$A:$B,2,FALSE) -> Bethlehem
A7: e | B7: Sars | C7: =COUNTIF(D7:M7,"bradford") -> 1 | D7: =VLOOKUP('Formula Workbook'!M6,Cities!$A:$B,2,FALSE) -> Reading | E7: =VLOOKUP('Formula Workbook'!N6,Cities!$A:$B,2,FALSE) -> Harrisburg | F7: =VLOOKUP('Formula Workbook'!O6,Cities!$A:$B,2,FALSE) -> Easton | G7: =VLOOKUP('Formula Workbook'!P6,Cities!$A:$B,2,FALSE) -> Bradford | H7: =VLOOKUP('Formula Workbook'!Q6,Cities!$A:$B,2,FALSE) -> Washington | I7: =VLOOKUP('Formula Workbook'!R6,Cities!$A:$B,2,FALSE) -> Altoona | J7: =VLOOKUP('Formula Workbook'!S6,Cities!$A:$B,2,FALSE) -> Franklin | K7: =VLOOKUP('Formula Workbook'!T6,Cities!$A:$B,2,FALSE) -> Greensburg | ... M7: =VLOOKUP('Formula Workbook'!V6,Cities!$A:$B,2,FALSE) -> Corry
A8: f | B8: Sars | C8: =COUNTIF(D8:M8,"bradford") -> 1 | D8: =VLOOKUP('Formula Workbook'!M7,Cities!$A:$B,2,FALSE) -> Philadelphia | E8: =VLOOKUP('Formula Workbook'!N7,Cities!$A:$B,2,FALSE) -> Beaver Falls | F8: =VLOOKUP('Formula Workbook'!O7,Cities!$A:$B,2,FALSE) -> Greensburg | G8: =VLOOKUP('Formula Workbook'!P7,Cities!$A:$B,2,FALSE) -> DuBois | H8: =VLOOKUP('Formula Workbook'!Q7,Cities!$A:$B,2,FALSE) -> Clairton | I8: =VLOOKUP('Formula Workbook'!R7,Cities!$A:$B,2,FALSE) -> Bradford | J8: =VLOOKUP('Formula Workbook'!S7,Cities!$A:$B,2,FALSE) -> Franklin | K8: =VLOOKUP('Formula Workbook'!T7,Cities!$A:$B,2,FALSE) -> Jeannette | ... M8: =VLOOKUP('Formula Workbook'!V7,Cities!$A:$B,2,FALSE) -> Aliquippa
A9: g | C9: =COUNTIF(D9:M9,"bradford") -> 0 | D9: =VLOOKUP('Formula Workbook'!M8,Cities!$A:$B,2,FALSE) -> Clairton | E9: =VLOOKUP('Formula Workbook'!N8,Cities!$A:$B,2,FALSE) -> Allentown | F9: =VLOOKUP('Formula Workbook'!O8,Cities!$A:$B,2,FALSE) -> DuBois | G9: =VLOOKUP('Formula Workbook'!P8,Cities!$A:$B,2,FALSE) -> Bethlehem | H9: =VLOOKUP('Formula Workbook'!Q8,Cities!$A:$B,2,FALSE) -> DuBois | I9: =VLOOKUP('Formula Workbook'!R8,Cities!$A:$B,2,FALSE) -> Easton | J9: =VLOOKUP('Formula Workbook'!S8,Cities!$A:$B,2,FALSE) -> Wilkes-Barre | K9: =VLOOKUP('Formula Workbook'!T8,Cities!$A:$B,2,FALSE) -> Reading | ... M9: =VLOOKUP('Formula Workbook'!V8,Cities!$A:$B,2,FALSE) -> Bethlehem
A10: h | C10: =COUNTIF(D10:M10,"bradford") -> 0 | D10: =VLOOKUP('Formula Workbook'!M9,Cities!$A:$B,2,FALSE) -> Corry | E10: =VLOOKUP('Formula Workbook'!N9,Cities!$A:$B,2,FALSE) -> Greensburg | F10: =VLOOKUP('Formula Workbook'!O9,Cities!$A:$B,2,FALSE) -> Greensburg | G10: =VLOOKUP('Formula Workbook'!P9,Cities!$A:$B,2,FALSE) -> Aliquippa | H10: =VLOOKUP('Formula Workbook'!Q9,Cities!$A:$B,2,FALSE) -> Washington | I10: =VLOOKUP('Formula Workbook'!R9,Cities!$A:$B,2,FALSE) -> DuBois | J10: =VLOOKUP('Formula Workbook'!S9,Cities!$A:$B,2,FALSE) -> Reading | K10: =VLOOKUP('Formula Workbook'!T9,Cities!$A:$B,2,FALSE) -> Reading | ... M10: =VLOOKUP('Formula Workbook'!V9,Cities!$A:$B,2,FALSE) -> Connellsville
A11: i | C11: =COUNTIF(D11:M11,"bradford") -> 0 | D11: =VLOOKUP('Formula Workbook'!M10,Cities!$A:$B,2,FALSE) -> Altoona | E11: =VLOOKUP('Formula Workbook'!N10,Cities!$A:$B,2,FALSE) -> Clairton | F11: =VLOOKUP('Formula Workbook'!O10,Cities!$A:$B,2,FALSE) -> Duquesne | G11: =VLOOKUP('Formula Workbook'!P10,Cities!$A:$B,2,FALSE) -> Philadelphia | H11: =VLOOKUP('Formula Workbook'!Q10,Cities!$A:$B,2,FALSE) -> Jeannette | I11: =VLOOKUP('Formula Workbook'!R10,Cities!$A:$B,2,FALSE) -> Connellsville | J11: =VLOOKUP('Formula Workbook'!S10,Cities!$A:$B,2,FALSE) -> Aliquippa | K11: =VLOOKUP('Formula Workbook'!T10,Cities!$A:$B,2,FALSE) -> Connellsville | ... M11: =VLOOKUP('Formula Workbook'!V10,Cities!$A:$B,2,FALSE) -> Corry
A12: j | C12: =COUNTIF(D12:M12,"bradford") -> 0 | D12: =VLOOKUP('Formula Workbook'!M11,Cities!$A:$B,2,FALSE) -> Jeannette | E12: =VLOOKUP('Formula Workbook'!N11,Cities!$A:$B,2,FALSE) -> Hermitage | F12: =VLOOKUP('Formula Workbook'!O11,Cities!$A:$B,2,FALSE) -> Reading | G12: =VLOOKUP('Formula Workbook'!P11,Cities!$A:$B,2,FALSE) -> Connellsville | H12: =VLOOKUP('Formula Workbook'!Q11,Cities!$A:$B,2,FALSE) -> Easton | I12: =VLOOKUP('Formula Workbook'!R11,Cities!$A:$B,2,FALSE) -> Altoona | J12: =VLOOKUP('Formula Workbook'!S11,Cities!$A:$B,2,FALSE) -> Greensburg | K12: =VLOOKUP('Formula Workbook'!T11,Cities!$A:$B,2,FALSE) -> Washington | ... M12: =VLOOKUP('Formula Workbook'!V11,Cities!$A:$B,2,FALSE) -> Clairton
A13: k | B13: Sars | C13: =COUNTIF(D13:M13,"bradford") -> 1 | D13: =VLOOKUP('Formula Workbook'!M12,Cities!$A:$B,2,FALSE) -> Bradford | E13: =VLOOKUP('Formula Workbook'!N12,Cities!$A:$B,2,FALSE) -> Hazleton | F13: =VLOOKUP('Formula Workbook'!O12,Cities!$A:$B,2,FALSE) -> Wilkes-Barre | G13: =VLOOKUP('Formula Workbook'!P12,Cities!$A:$B,2,FALSE) -> Aliquippa | H13: =VLOOKUP('Formula Workbook'!Q12,Cities!$A:$B,2,FALSE) -> Easton | I13: =VLOOKUP('Formula Workbook'!R12,Cities!$A:$B,2,FALSE) -> Pittsburgh | J13: =VLOOKUP('Formula Workbook'!S12,Cities!$A:$B,2,FALSE) -> Easton | K13: =VLOOKUP('Formula Workbook'!T12,Cities!$A:$B,2,FALSE) -> Connellsville | ... M13: =VLOOKUP('Formula Workbook'!V12,Cities!$A:$B,2,FALSE) -> Pittsburgh
A14: l | C14: =COUNTIF(D14:M14,"bradford") -> 0 | D14: =VLOOKUP('Formula Workbook'!M13,Cities!$A:$B,2,FALSE) -> Clairton | E14: =VLOOKUP('Formula Workbook'!N13,Cities!$A:$B,2,FALSE) -> Greensburg | F14: =VLOOKUP('Formula Workbook'!O13,Cities!$A:$B,2,FALSE) -> Easton | G14: =VLOOKUP('Formula Workbook'!P13,Cities!$A:$B,2,FALSE) -> Washington | H14: =VLOOKUP('Formula Workbook'!Q13,Cities!$A:$B,2,FALSE) -> Corry | I14: =VLOOKUP('Formula Workbook'!R13,Cities!$A:$B,2,FALSE) -> Jeannette | J14: =VLOOKUP('Formula Workbook'!S13,Cities!$A:$B,2,FALSE) -> Franklin | K14: =VLOOKUP('Formula Workbook'!T13,Cities!$A:$B,2,FALSE) -> Chester | ... M14: =VLOOKUP('Formula Workbook'!V13,Cities!$A:$B,2,FALSE) -> Beaver Falls
A15: m | B15: Sars | C15: =COUNTIF(D15:M15,"bradford") -> 1 | D15: =VLOOKUP('Formula Workbook'!M14,Cities!$A:$B,2,FALSE) -> Chester | E15: =VLOOKUP('Formula Workbook'!N14,Cities!$A:$B,2,FALSE) -> Beaver Falls | F15: =VLOOKUP('Formula Workbook'!O14,Cities!$A:$B,2,FALSE) -> Aliquippa | G15: =VLOOKUP('Formula Workbook'!P14,Cities!$A:$B,2,FALSE) -> Bethlehem | H15: =VLOOKUP('Formula Workbook'!Q14,Cities!$A:$B,2,FALSE) -> Corry | I15: =VLOOKUP('Formula Workbook'!R14,Cities!$A:$B,2,FALSE) -> Easton | J15: =VLOOKUP('Formula Workbook'!S14,Cities!$A:$B,2,FALSE) -> Beaver Falls | K15: =VLOOKUP('Formula Workbook'!T14,Cities!$A:$B,2,FALSE) -> Aliquippa | ... M15: =VLOOKUP('Formula Workbook'!V14,Cities!$A:$B,2,FALSE) -> Jeannette
A16: n | C16: =COUNTIF(D16:M16,"bradford") -> 0 | D16: =VLOOKUP('Formula Workbook'!M15,Cities!$A:$B,2,FALSE) -> Erie | E16: =VLOOKUP('Formula Workbook'!N15,Cities!$A:$B,2,FALSE) -> Altoona | F16: =VLOOKUP('Formula Workbook'!O15,Cities!$A:$B,2,FALSE) -> Greensburg | G16: =VLOOKUP('Formula Workbook'!P15,Cities!$A:$B,2,FALSE) -> Butler | H16: =VLOOKUP('Formula Workbook'!Q15,Cities!$A:$B,2,FALSE) -> Wilkes-Barre | I16: =VLOOKUP('Formula Workbook'!R15,Cities!$A:$B,2,FALSE) -> Washington | J16: =VLOOKUP('Formula Workbook'!S15,Cities!$A:$B,2,FALSE) -> Corry | K16: =VLOOKUP('Formula Workbook'!T15,Cities!$A:$B,2,FALSE) -> DuBois | ... M16: =VLOOKUP('Formula Workbook'!V15,Cities!$A:$B,2,FALSE) -> Franklin
A17: o | C17: =COUNTIF(D17:M17,"bradford") -> 0 | D17: =VLOOKUP('Formula Workbook'!M16,Cities!$A:$B,2,FALSE) -> Philadelphia | E17: =VLOOKUP('Formula Workbook'!N16,Cities!$A:$B,2,FALSE) -> Franklin | F17: =VLOOKUP('Formula Workbook'!O16,Cities!$A:$B,2,FALSE) -> Beaver Falls | G17: =VLOOKUP('Formula Workbook'!P16,Cities!$A:$B,2,FALSE) -> Harrisburg | H17: =VLOOKUP('Formula Workbook'!Q16,Cities!$A:$B,2,FALSE) -> Philadelphia | I17: =VLOOKUP('Formula Workbook'!R16,Cities!$A:$B,2,FALSE) -> Erie | J17: =VLOOKUP('Formula Workbook'!S16,Cities!$A:$B,2,FALSE) -> DuBois | K17: =VLOOKUP('Formula Workbook'!T16,Cities!$A:$B,2,FALSE) -> Pittsburgh | ... M17: =VLOOKUP('Formula Workbook'!V16,Cities!$A:$B,2,FALSE) -> Franklin
A18: p | B18: Sars | C18: =COUNTIF(D18:M18,"bradford") -> 1 | D18: =VLOOKUP('Formula Workbook'!M17,Cities!$A:$B,2,FALSE) -> Butler | E18: =VLOOKUP('Formula Workbook'!N17,Cities!$A:$B,2,FALSE) -> Hazleton | F18: =VLOOKUP('Formula Workbook'!O17,Cities!$A:$B,2,FALSE) -> Butler | G18: =VLOOKUP('Formula Workbook'!P17,Cities!$A:$B,2,FALSE) -> Chester | H18: =VLOOKUP('Formula Workbook'!Q17,Cities!$A:$B,2,FALSE) -> Bradford | I18: =VLOOKUP('Formula Workbook'!R17,Cities!$A:$B,2,FALSE) -> Hazleton | J18: =VLOOKUP('Formula Workbook'!S17,Cities!$A:$B,2,FALSE) -> Duquesne | K18: =VLOOKUP('Formula Workbook'!T17,Cities!$A:$B,2,FALSE) -> Altoona | ... M18: =VLOOKUP('Formula Workbook'!V17,Cities!$A:$B,2,FALSE) -> Connellsville
A19: q | C19: =COUNTIF(D19:M19,"bradford") -> 0 | D19: =VLOOKUP('Formula Workbook'!M18,Cities!$A:$B,2,FALSE) -> Corry | E19: =VLOOKUP('Formula Workbook'!N18,Cities!$A:$B,2,FALSE) -> Duquesne | F19: =VLOOKUP('Formula Workbook'!O18,Cities!$A:$B,2,FALSE) -> Bethlehem | G19: =VLOOKUP('Formula Workbook'!P18,Cities!$A:$B,2,FALSE) -> Wilkes-Barre | H19: =VLOOKUP('Formula Workbook'!Q18,Cities!$A:$B,2,FALSE) -> Erie | I19: =VLOOKUP('Formula Workbook'!R18,Cities!$A:$B,2,FALSE) -> Corry | J19: =VLOOKUP('Formula Workbook'!S18,Cities!$A:$B,2,FALSE) -> Clairton | K19: =VLOOKUP('Formula Workbook'!T18,Cities!$A:$B,2,FALSE) -> Chester | ... M19: =VLOOKUP('Formula Workbook'!V18,Cities!$A:$B,2,FALSE) -> Hazleton
A20: r | C20: =COUNTIF(D20:M20,"bradford") -> 0 | D20: =VLOOKUP('Formula Workbook'!M19,Cities!$A:$B,2,FALSE) -> Butler | E20: =VLOOKUP('Formula Workbook'!N19,Cities!$A:$B,2,FALSE) -> Philadelphia | F20: =VLOOKUP('Formula Workbook'!O19,Cities!$A:$B,2,FALSE) -> Harrisburg | G20: =VLOOKUP('Formula Workbook'!P19,Cities!$A:$B,2,FALSE) -> Franklin | H20: =VLOOKUP('Formula Workbook'!Q19,Cities!$A:$B,2,FALSE) -> Wilkes-Barre | I20: =VLOOKUP('Formula Workbook'!R19,Cities!$A:$B,2,FALSE) -> Allentown | J20: =VLOOKUP('Formula Workbook'!S19,Cities!$A:$B,2,FALSE) -> Beaver Falls | K20: =VLOOKUP('Formula Workbook'!T19,Cities!$A:$B,2,FALSE) -> Easton | ... M20: =VLOOKUP('Formula Workbook'!V19,Cities!$A:$B,2,FALSE) -> Erie
A21: s | B21: Sars | C21: =COUNTIF(D21:M21,"bradford") -> 1 | D21: =VLOOKUP('Formula Workbook'!M20,Cities!$A:$B,2,FALSE) -> Greensburg | E21: =VLOOKUP('Formula Workbook'!N20,Cities!$A:$B,2,FALSE) -> Butler | F21: =VLOOKUP('Formula Workbook'!O20,Cities!$A:$B,2,FALSE) -> Jeannette | G21: =VLOOKUP('Formula Workbook'!P20,Cities!$A:$B,2,FALSE) -> Easton | H21: =VLOOKUP('Formula Workbook'!Q20,Cities!$A:$B,2,FALSE) -> Reading | I21: =VLOOKUP('Formula Workbook'!R20,Cities!$A:$B,2,FALSE) -> Erie | J21: =VLOOKUP('Formula Workbook'!S20,Cities!$A:$B,2,FALSE) -> Philadelphia | K21: =VLOOKUP('Formula Workbook'!T20,Cities!$A:$B,2,FALSE) -> Philadelphia | ... M21: =VLOOKUP('Formula Workbook'!V20,Cities!$A:$B,2,FALSE) -> Wilkes-Barre
A22: t | C22: =COUNTIF(D22:M22,"bradford") -> 0 | D22: =VLOOKUP('Formula Workbook'!M21,Cities!$A:$B,2,FALSE) -> Chester | E22: =VLOOKUP('Formula Workbook'!N21,Cities!$A:$B,2,FALSE) -> Jeannette | F22: =VLOOKUP('Formula Workbook'!O21,Cities!$A:$B,2,FALSE) -> Bethlehem | G22: =VLOOKUP('Formula Workbook'!P21,Cities!$A:$B,2,FALSE) -> Wilkes-Barre | H22: =VLOOKUP('Formula Workbook'!Q21,Cities!$A:$B,2,FALSE) -> Butler | I22: =VLOOKUP('Formula Workbook'!R21,Cities!$A:$B,2,FALSE) -> Altoona | J22: =VLOOKUP('Formula Workbook'!S21,Cities!$A:$B,2,FALSE) -> Franklin | K22: =VLOOKUP('Formula Workbook'!T21,Cities!$A:$B,2,FALSE) -> Hazleton | ... M22: =VLOOKUP('Formula Workbook'!V21,Cities!$A:$B,2,FALSE) -> Aliquippa
A23: u | C23: =COUNTIF(D23:M23,"bradford") -> 0 | D23: =VLOOKUP('Formula Workbook'!M22,Cities!$A:$B,2,FALSE) -> Wilkes-Barre | E23: =VLOOKUP('Formula Workbook'!N22,Cities!$A:$B,2,FALSE) -> DuBois | F23: =VLOOKUP('Formula Workbook'!O22,Cities!$A:$B,2,FALSE) -> Pittsburgh | G23: =VLOOKUP('Formula Workbook'!P22,Cities!$A:$B,2,FALSE) -> Corry | H23: =VLOOKUP('Formula Workbook'!Q22,Cities!$A:$B,2,FALSE) -> Aliquippa | I23: =VLOOKUP('Formula Workbook'!R22,Cities!$A:$B,2,FALSE) -> Erie | J23: =VLOOKUP('Formula Workbook'!S22,Cities!$A:$B,2,FALSE) -> DuBois | K23: =VLOOKUP('Formula Workbook'!T22,Cities!$A:$B,2,FALSE) -> Aliquippa | ... M23: =VLOOKUP('Formula Workbook'!V22,Cities!$A:$B,2,FALSE) -> Aliquippa
A24: v | C24: =COUNTIF(D24:M24,"bradford") -> 0 | D24: =VLOOKUP('Formula Workbook'!M23,Cities!$A:$B,2,FALSE) -> Hermitage | E24: =VLOOKUP('Formula Workbook'!N23,Cities!$A:$B,2,FALSE) -> Corry | F24: =VLOOKUP('Formula Workbook'!O23,Cities!$A:$B,2,FALSE) -> Wilkes-Barre | G24: =VLOOKUP('Formula Workbook'!P23,Cities!$A:$B,2,FALSE) -> Hermitage | H24: =VLOOKUP('Formula Workbook'!Q23,Cities!$A:$B,2,FALSE) -> Pittsburgh | I24: =VLOOKUP('Formula Workbook'!R23,Cities!$A:$B,2,FALSE) -> Altoona | J24: =VLOOKUP('Formula Workbook'!S23,Cities!$A:$B,2,FALSE) -> Hazleton | K24: =VLOOKUP('Formula Workbook'!T23,Cities!$A:$B,2,FALSE) -> Clairton | ... M24: =VLOOKUP('Formula Workbook'!V23,Cities!$A:$B,2,FALSE) -> Clairton
A25: w | C25: =COUNTIF(D25:M25,"bradford") -> 0 | D25: =VLOOKUP('Formula Workbook'!M24,Cities!$A:$B,2,FALSE) -> Bethlehem | E25: =VLOOKUP('Formula Workbook'!N24,Cities!$A:$B,2,FALSE) -> Chester | F25: =VLOOKUP('Formula Workbook'!O24,Cities!$A:$B,2,FALSE) -> Allentown | G25: =VLOOKUP('Formula Workbook'!P24,Cities!$A:$B,2,FALSE) -> Aliquippa | H25: =VLOOKUP('Formula Workbook'!Q24,Cities!$A:$B,2,FALSE) -> Wilkes-Barre | I25: =VLOOKUP('Formula Workbook'!R24,Cities!$A:$B,2,FALSE) -> Duquesne | J25: =VLOOKUP('Formula Workbook'!S24,Cities!$A:$B,2,FALSE) -> Duquesne | K25: =VLOOKUP('Formula Workbook'!T24,Cities!$A:$B,2,FALSE) -> Hermitage | ... M25: =VLOOKUP('Formula Workbook'!V24,Cities!$A:$B,2,FALSE) -> Altoona
A26: x | C26: =COUNTIF(D26:M26,"bradford") -> 0 | D26: =VLOOKUP('Formula Workbook'!M25,Cities!$A:$B,2,FALSE) -> Duquesne | E26: =VLOOKUP('Formula Workbook'!N25,Cities!$A:$B,2,FALSE) -> DuBois | F26: =VLOOKUP('Formula Workbook'!O25,Cities!$A:$B,2,FALSE) -> Duquesne | G26: =VLOOKUP('Formula Workbook'!P25,Cities!$A:$B,2,FALSE) -> Hermitage | H26: =VLOOKUP('Formula Workbook'!Q25,Cities!$A:$B,2,FALSE) -> Harrisburg | I26: =VLOOKUP('Formula Workbook'!R25,Cities!$A:$B,2,FALSE) -> Allentown | J26: =VLOOKUP('Formula Workbook'!S25,Cities!$A:$B,2,FALSE) -> Aliquippa | K26: =VLOOKUP('Formula Workbook'!T25,Cities!$A:$B,2,FALSE) -> Hazleton | ... M26: =VLOOKUP('Formula Workbook'!V25,Cities!$A:$B,2,FALSE) -> Hazleton
A27: y | C27: =COUNTIF(D27:M27,"bradford") -> 0 | D27: =VLOOKUP('Formula Workbook'!M26,Cities!$A:$B,2,FALSE) -> Harrisburg | E27: =VLOOKUP('Formula Workbook'!N26,Cities!$A:$B,2,FALSE) -> DuBois | F27: =VLOOKUP('Formula Workbook'!O26,Cities!$A:$B,2,FALSE) -> Pittsburgh | G27: =VLOOKUP('Formula Workbook'!P26,Cities!$A:$B,2,FALSE) -> Reading | H27: =VLOOKUP('Formula Workbook'!Q26,Cities!$A:$B,2,FALSE) -> Allentown | I27: =VLOOKUP('Formula Workbook'!R26,Cities!$A:$B,2,FALSE) -> Hermitage | J27: =VLOOKUP('Formula Workbook'!S26,Cities!$A:$B,2,FALSE) -> Washington | K27: =VLOOKUP('Formula Workbook'!T26,Cities!$A:$B,2,FALSE) -> Allentown | ... M27: =VLOOKUP('Formula Workbook'!V26,Cities!$A:$B,2,FALSE) -> Bethlehem
A28: z | C28: =COUNTIF(D28:M28,"bradford") -> 0 | D28: =VLOOKUP('Formula Workbook'!M27,Cities!$A:$B,2,FALSE) -> Clairton | E28: =VLOOKUP('Formula Workbook'!N27,Cities!$A:$B,2,FALSE) -> Easton | F28: =VLOOKUP('Formula Workbook'!O27,Cities!$A:$B,2,FALSE) -> Aliquippa | G28: =VLOOKUP('Formula Workbook'!P27,Cities!$A:$B,2,FALSE) -> Allentown | H28: =VLOOKUP('Formula Workbook'!Q27,Cities!$A:$B,2,FALSE) -> Connellsville | I28: =VLOOKUP('Formula Workbook'!R27,Cities!$A:$B,2,FALSE) -> Jeannette | J28: =VLOOKUP('Formula Workbook'!S27,Cities!$A:$B,2,FALSE) -> Jeannette | K28: =VLOOKUP('Formula Workbook'!T27,Cities!$A:$B,2,FALSE) -> Connellsville | ... M28: =VLOOKUP('Formula Workbook'!V27,Cities!$A:$B,2,FALSE) -> Chester

Sheet Scenerio 3
G1: Scenerio 3 | J1: Channel:
A2: People | C2: washington | D2: Location 1 | E2: Location 2 | F2: Location 3 | G2: Location 4 | H2: Location 5 | I2: Location 6 | J2: Location 7 | K2: Location 8 | L2: Location 9 | M2: Location 10
A3: a | C3: =COUNTIF(D3:M3,$C$2) -> 0 | D3: =VLOOKUP('Formula Workbook'!C2,Cities!$A:$B,2,FALSE) -> Pittsburgh | E3: =VLOOKUP('Formula Workbook'!D2,Cities!$A:$B,2,FALSE) -> Erie | F3: =VLOOKUP('Formula Workbook'!E2,Cities!$A:$B,2,FALSE) -> Clairton | G3: =VLOOKUP('Formula Workbook'!F2,Cities!$A:$B,2,FALSE) -> Chester | H3: =VLOOKUP('Formula Workbook'!G2,Cities!$A:$B,2,FALSE) -> Harrisburg | I3: =VLOOKUP('Formula Workbook'!H2,Cities!$A:$B,2,FALSE) -> Easton | J3: =VLOOKUP('Formula Workbook'!I2,Cities!$A:$B,2,FALSE) -> Hermitage | K3: =VLOOKUP('Formula Workbook'!J2,Cities!$A:$B,2,FALSE) -> Pittsburgh | ... M3: =VLOOKUP('Formula Workbook'!L2,Cities!$A:$B,2,FALSE) -> Altoona
A4: b | C4: =COUNTIF(D4:M4,$C$2) -> 0 | D4: =VLOOKUP('Formula Workbook'!C3,Cities!$A:$B,2,FALSE) -> Corry | E4: =VLOOKUP('Formula Workbook'!D3,Cities!$A:$B,2,FALSE) -> Altoona | F4: =VLOOKUP('Formula Workbook'!E3,Cities!$A:$B,2,FALSE) -> Beaver Falls | G4: =VLOOKUP('Formula Workbook'!F3,Cities!$A:$B,2,FALSE) -> Jeannette | H4: =VLOOKUP('Formula Workbook'!G3,Cities!$A:$B,2,FALSE) -> Bradford | I4: =VLOOKUP('Formula Workbook'!H3,Cities!$A:$B,2,FALSE) -> Beaver Falls | J4: =VLOOKUP('Formula Workbook'!I3,Cities!$A:$B,2,FALSE) -> Reading | K4: Scranton | L4: =VLOOKUP('Formula Workbook'!K3,Cities!$A:$B,2,FALSE) -> Duquesne | M4: =VLOOKUP('Formula Workbook'!L3,Cities!$A:$B,2,FALSE) -> Allentown
A5: c | B5: E. coli | C5: =COUNTIF(D5:M5,$C$2) -> 1 | D5: =VLOOKUP('Formula Workbook'!C4,Cities!$A:$B,2,FALSE) -> Allentown | E5: =VLOOKUP('Formula Workbook'!D4,Cities!$A:$B,2,FALSE) -> Aliquippa | F5: =VLOOKUP('Formula Workbook'!E4,Cities!$A:$B,2,FALSE) -> Reading | G5: =VLOOKUP('Formula Workbook'!F4,Cities!$A:$B,2,FALSE) -> Bethlehem | H5: Scranton | I5: =VLOOKUP('Formula Workbook'!H4,Cities!$A:$B,2,FALSE) -> Harrisburg | J5: =VLOOKUP('Formula Workbook'!I4,Cities!$A:$B,2,FALSE) -> Washington | K5: =VLOOKUP('Formula Workbook'!J4,Cities!$A:$B,2,FALSE) -> Connellsville | L5: =VLOOKUP('Formula Workbook'!K4,Cities!$A:$B,2,FALSE) -> Clairton | M5: =VLOOKUP('Formula Workbook'!L4,Cities!$A:$B,2,FALSE) -> Duquesne
A6: d | C6: =COUNTIF(D6:M6,$C$2) -> 0 | D6: =VLOOKUP('Formula Workbook'!C5,Cities!$A:$B,2,FALSE) -> Hermitage | E6: =VLOOKUP('Formula Workbook'!D5,Cities!$A:$B,2,FALSE) -> Harrisburg | F6: =VLOOKUP('Formula Workbook'!E5,Cities!$A:$B,2,FALSE) -> Corry | G6: =VLOOKUP('Formula Workbook'!F5,Cities!$A:$B,2,FALSE) -> Bethlehem | H6: =VLOOKUP('Formula Workbook'!G5,Cities!$A:$B,2,FALSE) -> Franklin | I6: =VLOOKUP('Formula Workbook'!H5,Cities!$A:$B,2,FALSE) -> Connellsville | J6: Scranton | K6: =VLOOKUP('Formula Workbook'!J5,Cities!$A:$B,2,FALSE) -> Harrisburg | L6: =VLOOKUP('Formula Workbook'!K5,Cities!$A:$B,2,FALSE) -> Hermitage | M6: =VLOOKUP('Formula Workbook'!L5,Cities!$A:$B,2,FALSE) -> Beaver Falls
A7: e | B7: E. coli | C7: =COUNTIF(D7:M7,$C$2) -> 1 | D7: =VLOOKUP('Formula Workbook'!C6,Cities!$A:$B,2,FALSE) -> Washington | E7: =VLOOKUP('Formula Workbook'!D6,Cities!$A:$B,2,FALSE) -> Harrisburg | F7: =VLOOKUP('Formula Workbook'!E6,Cities!$A:$B,2,FALSE) -> Franklin | G7: =VLOOKUP('Formula Workbook'!F6,Cities!$A:$B,2,FALSE) -> Bradford | H7: =VLOOKUP('Formula Workbook'!G6,Cities!$A:$B,2,FALSE) -> Butler | I7: =VLOOKUP('Formula Workbook'!H6,Cities!$A:$B,2,FALSE) -> Bradford | J7: =VLOOKUP('Formula Workbook'!I6,Cities!$A:$B,2,FALSE) -> Connellsville | K7: =VLOOKUP('Formula Workbook'!J6,Cities!$A:$B,2,FALSE) -> Erie | ... M7: =VLOOKUP('Formula Workbook'!L6,Cities!$A:$B,2,FALSE) -> Reading
A8: f | B8: E. coli | C8: =COUNTIF(D8:M8,$C$2) -> 1 | D8: =VLOOKUP('Formula Workbook'!C7,Cities!$A:$B,2,FALSE) -> Altoona | E8: =VLOOKUP('Formula Workbook'!D7,Cities!$A:$B,2,FALSE) -> Easton | F8: =VLOOKUP('Formula Workbook'!E7,Cities!$A:$B,2,FALSE) -> DuBois | G8: =VLOOKUP('Formula Workbook'!F7,Cities!$A:$B,2,FALSE) -> Bradford | H8: =VLOOKUP('Formula Workbook'!G7,Cities!$A:$B,2,FALSE) -> Easton | I8: =VLOOKUP('Formula Workbook'!H7,Cities!$A:$B,2,FALSE) -> Aliquippa | J8: =VLOOKUP('Formula Workbook'!I7,Cities!$A:$B,2,FALSE) -> Erie | K8: =VLOOKUP('Formula Workbook'!J7,Cities!$A:$B,2,FALSE) -> Washington | ... M8: =VLOOKUP('Formula Workbook'!L7,Cities!$A:$B,2,FALSE) -> Philadelphia
A9: g | C9: =COUNTIF(D9:M9,$C$2) -> 0 | D9: Scranton | E9: =VLOOKUP('Formula Workbook'!D8,Cities!$A:$B,2,FALSE) -> Hermitage | F9: =VLOOKUP('Formula Workbook'!E8,Cities!$A:$B,2,FALSE) -> Bethlehem | G9: =VLOOKUP('Formula Workbook'!F8,Cities!$A:$B,2,FALSE) -> Chester | H9: =VLOOKUP('Formula Workbook'!G8,Cities!$A:$B,2,FALSE) -> Hazleton | I9: =VLOOKUP('Formula Workbook'!H8,Cities!$A:$B,2,FALSE) -> Franklin | J9: =VLOOKUP('Formula Workbook'!I8,Cities!$A:$B,2,FALSE) -> Clairton | K9: =VLOOKUP('Formula Workbook'!J8,Cities!$A:$B,2,FALSE) -> Harrisburg | L9: =VLOOKUP('Formula Workbook'!K8,Cities!$A:$B,2,FALSE) -> Aliquippa | M9: =VLOOKUP('Formula Workbook'!L8,Cities!$A:$B,2,FALSE) -> Greensburg
A10: h | C10: =COUNTIF(D10:M10,$C$2) -> 0 | D10: =VLOOKUP('Formula Workbook'!C9,Cities!$A:$B,2,FALSE) -> Duquesne | E10: =VLOOKUP('Formula Workbook'!D9,Cities!$A:$B,2,FALSE) -> Reading | F10: =VLOOKUP('Formula Workbook'!E9,Cities!$A:$B,2,FALSE) -> Beaver Falls | G10: =VLOOKUP('Formula Workbook'!F9,Cities!$A:$B,2,FALSE) -> Philadelphia | H10: =VLOOKUP('Formula Workbook'!G9,Cities!$A:$B,2,FALSE) -> Erie | I10: =VLOOKUP('Formula Workbook'!H9,Cities!$A:$B,2,FALSE) -> DuBois | J10: =VLOOKUP('Formula Workbook'!I9,Cities!$A:$B,2,FALSE) -> Erie | K10: =VLOOKUP('Formula Workbook'!J9,Cities!$A:$B,2,FALSE) -> Franklin | ... M10: =VLOOKUP('Formula Workbook'!L9,Cities!$A:$B,2,FALSE) -> Chester
A11: i | B11: E. coli | C11: =COUNTIF(D11:M11,$C$2) -> 1 | D11: =VLOOKUP('Formula Workbook'!C10,Cities!$A:$B,2,FALSE) -> Chester | E11: =VLOOKUP('Formula Workbook'!D10,Cities!$A:$B,2,FALSE) -> Washington | F11: =VLOOKUP('Formula Workbook'!E10,Cities!$A:$B,2,FALSE) -> Duquesne | G11: =VLOOKUP('Formula Workbook'!F10,Cities!$A:$B,2,FALSE) -> Bradford | H11: =VLOOKUP('Formula Workbook'!G10,Cities!$A:$B,2,FALSE) -> Hazleton | I11: =VLOOKUP('Formula Workbook'!H10,Cities!$A:$B,2,FALSE) -> Easton | J11: =VLOOKUP('Formula Workbook'!I10,Cities!$A:$B,2,FALSE) -> Franklin | K11: =VLOOKUP('Formula Workbook'!J10,Cities!$A:$B,2,FALSE) -> Connellsville | ... M11: =VLOOKUP('Formula Workbook'!L10,Cities!$A:$B,2,FALSE) -> Bradford
A12: j | C12: =COUNTIF(D12:M12,$C$2) -> 0 | D12: =VLOOKUP('Formula Workbook'!C11,Cities!$A:$B,2,FALSE) -> Altoona | E12: =VLOOKUP('Formula Workbook'!D11,Cities!$A:$B,2,FALSE) -> Aliquippa | F12: =VLOOKUP('Formula Workbook'!E11,Cities!$A:$B,2,FALSE) -> Greensburg | G12: =VLOOKUP('Formula Workbook'!F11,Cities!$A:$B,2,FALSE) -> Connellsville | H12: =VLOOKUP('Formula Workbook'!G11,Cities!$A:$B,2,FALSE) -> Franklin | I12: =VLOOKUP('Formula Workbook'!H11,Cities!$A:$B,2,FALSE) -> Franklin | J12: =VLOOKUP('Formula Workbook'!I11,Cities!$A:$B,2,FALSE) -> Corry | K12: =VLOOKUP('Formula Workbook'!J11,Cities!$A:$B,2,FALSE) -> Altoona | ... M12: =VLOOKUP('Formula Workbook'!L11,Cities!$A:$B,2,FALSE) -> Corry
A13: k | C13: =COUNTIF(D13:M13,$C$2) -> 0 | D13: =VLOOKUP('Formula Workbook'!C12,Cities!$A:$B,2,FALSE) -> Bethlehem | E13: =VLOOKUP('Formula Workbook'!D12,Cities!$A:$B,2,FALSE) -> DuBois | F13: =VLOOKUP('Formula Workbook'!E12,Cities!$A:$B,2,FALSE) -> Corry | G13: =VLOOKUP('Formula Workbook'!F12,Cities!$A:$B,2,FALSE) -> Altoona | H13: =VLOOKUP('Formula Workbook'!G12,Cities!$A:$B,2,FALSE) -> Allentown | I13: =VLOOKUP('Formula Workbook'!H12,Cities!$A:$B,2,FALSE) -> Hermitage | J13: =VLOOKUP('Formula Workbook'!I12,Cities!$A:$B,2,FALSE) -> Hazleton | K13: =VLOOKUP('Formula Workbook'!J12,Cities!$A:$B,2,FALSE) -> Pittsburgh | ... M13: =VLOOKUP('Formula Workbook'!L12,Cities!$A:$B,2,FALSE) -> Erie
A14: l | C14: =COUNTIF(D14:M14,$C$2) -> 0 | D14: =VLOOKUP('Formula Workbook'!C13,Cities!$A:$B,2,FALSE) -> Easton | E14: =VLOOKUP('Formula Workbook'!D13,Cities!$A:$B,2,FALSE) -> Corry | F14: =VLOOKUP('Formula Workbook'!E13,Cities!$A:$B,2,FALSE) -> Beaver Falls | G14: =VLOOKUP('Formula Workbook'!F13,Cities!$A:$B,2,FALSE) -> Hazleton | H14: =VLOOKUP('Formula Workbook'!G13,Cities!$A:$B,2,FALSE) -> Allentown | I14: =VLOOKUP('Formula Workbook'!H13,Cities!$A:$B,2,FALSE) -> Beaver Falls | J14: =VLOOKUP('Formula Workbook'!I13,Cities!$A:$B,2,FALSE) -> Jeannette | K14: =VLOOKUP('Formula Workbook'!J13,Cities!$A:$B,2,FALSE) -> Harrisburg | L14: Scranton | M14: =VLOOKUP('Formula Workbook'!L13,Cities!$A:$B,2,FALSE) -> Allentown
A15: m | C15: =COUNTIF(D15:M15,$C$2) -> 0 | D15: =VLOOKUP('Formula Workbook'!C14,Cities!$A:$B,2,FALSE) -> Pittsburgh | E15: =VLOOKUP('Formula Workbook'!D14,Cities!$A:$B,2,FALSE) -> Easton | F15: =VLOOKUP('Formula Workbook'!E14,Cities!$A:$B,2,FALSE) -> Duquesne | G15: =VLOOKUP('Formula Workbook'!F14,Cities!$A:$B,2,FALSE) -> Allentown | H15: =VLOOKUP('Formula Workbook'!G14,Cities!$A:$B,2,FALSE) -> Greensburg | I15: =VLOOKUP('Formula Workbook'!H14,Cities!$A:$B,2,FALSE) -> Duquesne | J15: =VLOOKUP('Formula Workbook'!I14,Cities!$A:$B,2,FALSE) -> Pittsburgh | K15: Scranton | L15: =VLOOKUP('Formula Workbook'!K14,Cities!$A:$B,2,FALSE) -> DuBois | M15: =VLOOKUP('Formula Workbook'!L14,Cities!$A:$B,2,FALSE) -> Jeannette
A16: n | C16: =COUNTIF(D16:M16,$C$2) -> 0 | D16: =VLOOKUP('Formula Workbook'!C15,Cities!$A:$B,2,FALSE) -> Bradford | E16: =VLOOKUP('Formula Workbook'!D15,Cities!$A:$B,2,FALSE) -> Corry | F16: =VLOOKUP('Formula Workbook'!E15,Cities!$A:$B,2,FALSE) -> Connellsville | G16: =VLOOKUP('Formula Workbook'!F15,Cities!$A:$B,2,FALSE) -> Reading | H16: =VLOOKUP('Formula Workbook'!G15,Cities!$A:$B,2,FALSE) -> Easton | I16: =VLOOKUP('Formula Workbook'!H15,Cities!$A:$B,2,FALSE) -> Chester | J16: =VLOOKUP('Formula Workbook'!I15,Cities!$A:$B,2,FALSE) -> Pittsburgh | K16: =VLOOKUP('Formula Workbook'!J15,Cities!$A:$B,2,FALSE) -> Chester | ... M16: =VLOOKUP('Formula Workbook'!L15,Cities!$A:$B,2,FALSE) -> Chester
A17: o | C17: =COUNTIF(D17:M17,$C$2) -> 0 | D17: =VLOOKUP('Formula Workbook'!C16,Cities!$A:$B,2,FALSE) -> Bethlehem | E17: =VLOOKUP('Formula Workbook'!D16,Cities!$A:$B,2,FALSE) -> Duquesne | F17: =VLOOKUP('Formula Workbook'!E16,Cities!$A:$B,2,FALSE) -> Corry | G17: =VLOOKUP('Formula Workbook'!F16,Cities!$A:$B,2,FALSE) -> Harrisburg | H17: =VLOOKUP('Formula Workbook'!G16,Cities!$A:$B,2,FALSE) -> Bradford | I17: =VLOOKUP('Formula Workbook'!H16,Cities!$A:$B,2,FALSE) -> DuBois | J17: =VLOOKUP('Formula Workbook'!I16,Cities!$A:$B,2,FALSE) -> Duquesne | K17: =VLOOKUP('Formula Workbook'!J16,Cities!$A:$B,2,FALSE) -> Hermitage | ... M17: =VLOOKUP('Formula Workbook'!L16,Cities!$A:$B,2,FALSE) -> Philadelphia
A18: p | B18: E. coli | C18: =COUNTIF(D18:M18,$C$2) -> 1 | D18: =VLOOKUP('Formula Workbook'!C17,Cities!$A:$B,2,FALSE) -> Hazleton | E18: =VLOOKUP('Formula Workbook'!D17,Cities!$A:$B,2,FALSE) -> DuBois | F18: =VLOOKUP('Formula Workbook'!E17,Cities!$A:$B,2,FALSE) -> Chester | G18: =VLOOKUP('Formula Workbook'!F17,Cities!$A:$B,2,FALSE) -> Aliquippa | H18: Scranton | I18: =VLOOKUP('Formula Workbook'!H17,Cities!$A:$B,2,FALSE) -> Washington | J18: =VLOOKUP('Formula Workbook'!I17,Cities!$A:$B,2,FALSE) -> Hermitage | K18: =VLOOKUP('Formula Workbook'!J17,Cities!$A:$B,2,FALSE) -> Philadelphia | L18: =VLOOKUP('Formula Workbook'!K17,Cities!$A:$B,2,FALSE) -> Reading | M18: =VLOOKUP('Formula Workbook'!L17,Cities!$A:$B,2,FALSE) -> Aliquippa
A19: q | C19: =COUNTIF(D19:M19,$C$2) -> 0 | D19: =VLOOKUP('Formula Workbook'!C18,Cities!$A:$B,2,FALSE) -> Connellsville | E19: =VLOOKUP('Formula Workbook'!D18,Cities!$A:$B,2,FALSE) -> Bradford | F19: =VLOOKUP('Formula Workbook'!E18,Cities!$A:$B,2,FALSE) -> Corry | G19: =VLOOKUP('Formula Workbook'!F18,Cities!$A:$B,2,FALSE) -> Butler | H19: =VLOOKUP('Formula Workbook'!G18,Cities!$A:$B,2,FALSE) -> Corry | I19: =VLOOKUP('Formula Workbook'!H18,Cities!$A:$B,2,FALSE) -> Jeannette | J19: =VLOOKUP('Formula Workbook'!I18,Cities!$A:$B,2,FALSE) -> Franklin | K19: =VLOOKUP('Formula Workbook'!J18,Cities!$A:$B,2,FALSE) -> Hazleton | ... M19: =VLOOKUP('Formula Workbook'!L18,Cities!$A:$B,2,FALSE) -> Hazleton
A20: r | C20: =COUNTIF(D20:M20,$C$2) -> 0 | D20: =VLOOKUP('Formula Workbook'!C19,Cities!$A:$B,2,FALSE) -> Bethlehem | E20: =VLOOKUP('Formula Workbook'!D19,Cities!$A:$B,2,FALSE) -> Connellsville | F20: =VLOOKUP('Formula Workbook'!E19,Cities!$A:$B,2,FALSE) -> Franklin | G20: =VLOOKUP('Formula Workbook'!F19,Cities!$A:$B,2,FALSE) -> Aliquippa | H20: =VLOOKUP('Formula Workbook'!G19,Cities!$A:$B,2,FALSE) -> Pittsburgh | I20: =VLOOKUP('Formula Workbook'!H19,Cities!$A:$B,2,FALSE) -> Pittsburgh | J20: =VLOOKUP('Formula Workbook'!I19,Cities!$A:$B,2,FALSE) -> Reading | K20: =VLOOKUP('Formula Workbook'!J19,Cities!$A:$B,2,FALSE) -> Hazleton | ... M20: =VLOOKUP('Formula Workbook'!L19,Cities!$A:$B,2,FALSE) -> Easton
A21: s | B21: E. coli | C21: =COUNTIF(D21:M21,$C$2) -> 1 | D21: =VLOOKUP('Formula Workbook'!C20,Cities!$A:$B,2,FALSE) -> Washington | E21: =VLOOKUP('Formula Workbook'!D20,Cities!$A:$B,2,FALSE) -> Connellsville | F21: =VLOOKUP('Formula Workbook'!E20,Cities!$A:$B,2,FALSE) -> Duquesne | G21: =VLOOKUP('Formula Workbook'!F20,Cities!$A:$B,2,FALSE) -> Jeannette | H21: =VLOOKUP('Formula Workbook'!G20,Cities!$A:$B,2,FALSE) -> Corry | I21: =VLOOKUP('Formula Workbook'!H20,Cities!$A:$B,2,FALSE) -> Butler | J21: =VLOOKUP('Formula Workbook'!I20,Cities!$A:$B,2,FALSE) -> Harrisburg | K21: =VLOOKUP('Formula Workbook'!J20,Cities!$A:$B,2,FALSE) -> Reading | ... M21: =VLOOKUP('Formula Workbook'!L20,Cities!$A:$B,2,FALSE) -> Duquesne
A22: t | B22: E. coli | C22: =COUNTIF(D22:M22,$C$2) -> 1 | D22: =VLOOKUP('Formula Workbook'!C21,Cities!$A:$B,2,FALSE) -> Corry | E22: =VLOOKUP('Formula Workbook'!D21,Cities!$A:$B,2,FALSE) -> DuBois | F22: =VLOOKUP('Formula Workbook'!E21,Cities!$A:$B,2,FALSE) -> Allentown | G22: =VLOOKUP('Formula Workbook'!F21,Cities!$A:$B,2,FALSE) -> Erie | H22: =VLOOKUP('Formula Workbook'!G21,Cities!$A:$B,2,FALSE) -> Pittsburgh | I22: =VLOOKUP('Formula Workbook'!H21,Cities!$A:$B,2,FALSE) -> Allentown | J22: =VLOOKUP('Formula Workbook'!I21,Cities!$A:$B,2,FALSE) -> Hermitage | K22: Scranton | L22: =VLOOKUP('Formula Workbook'!K21,Cities!$A:$B,2,FALSE) -> Washington | M22: =VLOOKUP('Formula Workbook'!L21,Cities!$A:$B,2,FALSE) -> Butler
A23: u | C23: =COUNTIF(D23:M23,$C$2) -> 0 | D23: =VLOOKUP('Formula Workbook'!C22,Cities!$A:$B,2,FALSE) -> Pittsburgh | E23: =VLOOKUP('Formula Workbook'!D22,Cities!$A:$B,2,FALSE) -> Hermitage | F23: =VLOOKUP('Formula Workbook'!E22,Cities!$A:$B,2,FALSE) -> Duquesne | G23: =VLOOKUP('Formula Workbook'!F22,Cities!$A:$B,2,FALSE) -> Philadelphia | H23: =VLOOKUP('Formula Workbook'!G22,Cities!$A:$B,2,FALSE) -> Aliquippa | I23: =VLOOKUP('Formula Workbook'!H22,Cities!$A:$B,2,FALSE) -> Bradford | J23: =VLOOKUP('Formula Workbook'!I22,Cities!$A:$B,2,FALSE) -> Corry | K23: =VLOOKUP('Formula Workbook'!J22,Cities!$A:$B,2,FALSE) -> Connellsville | ... M23: =VLOOKUP('Formula Workbook'!L22,Cities!$A:$B,2,FALSE) -> Allentown
A24: v | B24: E. coli | C24: =COUNTIF(D24:M24,$C$2) -> 1 | D24: =VLOOKUP('Formula Workbook'!C23,Cities!$A:$B,2,FALSE) -> Corry | E24: =VLOOKUP('Formula Workbook'!D23,Cities!$A:$B,2,FALSE) -> Washington | F24: =VLOOKUP('Formula Workbook'!E23,Cities!$A:$B,2,FALSE) -> Altoona | G24: =VLOOKUP('Formula Workbook'!F23,Cities!$A:$B,2,FALSE) -> Chester | H24: =VLOOKUP('Formula Workbook'!G23,Cities!$A:$B,2,FALSE) -> Duquesne | I24: =VLOOKUP('Formula Workbook'!H23,Cities!$A:$B,2,FALSE) -> Hermitage | J24: =VLOOKUP('Formula Workbook'!I23,Cities!$A:$B,2,FALSE) -> Easton | K24: =VLOOKUP('Formula Workbook'!J23,Cities!$A:$B,2,FALSE) -> Erie | ... M24: =VLOOKUP('Formula Workbook'!L23,Cities!$A:$B,2,FALSE) -> Hermitage
A25: w | B25: E. coli | C25: =COUNTIF(D25:M25,$C$2) -> 1 | D25: =VLOOKUP('Formula Workbook'!C24,Cities!$A:$B,2,FALSE) -> Philadelphia | E25: Scranton | F25: =VLOOKUP('Formula Workbook'!E24,Cities!$A:$B,2,FALSE) -> Washington | G25: =VLOOKUP('Formula Workbook'!F24,Cities!$A:$B,2,FALSE) -> Easton | H25: =VLOOKUP('Formula Workbook'!G24,Cities!$A:$B,2,FALSE) -> Duquesne | I25: =VLOOKUP('Formula Workbook'!H24,Cities!$A:$B,2,FALSE) -> Jeannette | J25: =VLOOKUP('Formula Workbook'!I24,Cities!$A:$B,2,FALSE) -> Corry | K25: =VLOOKUP('Formula Workbook'!J24,Cities!$A:$B,2,FALSE) -> Greensburg | L25: =VLOOKUP('Formula Workbook'!K24,Cities!$A:$B,2,FALSE) -> Franklin | M25: Scranton
A26: x | B26: E. coli | C26: =COUNTIF(D26:M26,$C$2) -> 1 | D26: =VLOOKUP('Formula Workbook'!C25,Cities!$A:$B,2,FALSE) -> Altoona | E26: =VLOOKUP('Formula Workbook'!D25,Cities!$A:$B,2,FALSE) -> Altoona | F26: =VLOOKUP('Formula Workbook'!E25,Cities!$A:$B,2,FALSE) -> Philadelphia | G26: =VLOOKUP('Formula Workbook'!F25,Cities!$A:$B,2,FALSE) -> Clairton | H26: =VLOOKUP('Formula Workbook'!G25,Cities!$A:$B,2,FALSE) -> Franklin | I26: Scranton | J26: =VLOOKUP('Formula Workbook'!I25,Cities!$A:$B,2,FALSE) -> Harrisburg | K26: =VLOOKUP('Formula Workbook'!J25,Cities!$A:$B,2,FALSE) -> Washington | L26: =VLOOKUP('Formula Workbook'!K25,Cities!$A:$B,2,FALSE) -> Butler | M26: =VLOOKUP('Formula Workbook'!L25,Cities!$A:$B,2,FALSE) -> Pittsburgh
A27: y | B27: E. coli | C27: =COUNTIF(D27:M27,$C$2) -> 2 | D27: =VLOOKUP('Formula Workbook'!C26,Cities!$A:$B,2,FALSE) -> Allentown | E27: =VLOOKUP('Formula Workbook'!D26,Cities!$A:$B,2,FALSE) -> Chester | F27: =VLOOKUP('Formula Workbook'!E26,Cities!$A:$B,2,FALSE) -> Harrisburg | G27: =VLOOKUP('Formula Workbook'!F26,Cities!$A:$B,2,FALSE) -> Aliquippa | H27: =VLOOKUP('Formula Workbook'!G26,Cities!$A:$B,2,FALSE) -> Washington | I27: =VLOOKUP('Formula Workbook'!H26,Cities!$A:$B,2,FALSE) -> Corry | J27: =VLOOKUP('Formula Workbook'!I26,Cities!$A:$B,2,FALSE) -> Erie | K27: =VLOOKUP('Formula Workbook'!J26,Cities!$A:$B,2,FALSE) -> Jeannette | ... M27: =VLOOKUP('Formula Workbook'!L26,Cities!$A:$B,2,FALSE) -> Allentown
A28: z | B28: E. coli | C28: =COUNTIF(D28:M28,$C$2) -> 1 | D28: =VLOOKUP('Formula Workbook'!C27,Cities!$A:$B,2,FALSE) -> Aliquippa | E28: =VLOOKUP('Formula Workbook'!D27,Cities!$A:$B,2,FALSE) -> Hazleton | F28: =VLOOKUP('Formula Workbook'!E27,Cities!$A:$B,2,FALSE) -> Corry | G28: =VLOOKUP('Formula Workbook'!F27,Cities!$A:$B,2,FALSE) -> Washington | H28: =VLOOKUP('Formula Workbook'!G27,Cities!$A:$B,2,FALSE) -> Beaver Falls | I28: =VLOOKUP('Formula Workbook'!H27,Cities!$A:$B,2,FALSE) -> Connellsville | J28: =VLOOKUP('Formula Workbook'!I27,Cities!$A:$B,2,FALSE) -> Franklin | K28: Scranton | L28: =VLOOKUP('Formula Workbook'!K27,Cities!$A:$B,2,FALSE) -> Connellsville | M28: =VLOOKUP('Formula Workbook'!L27,Cities!$A:$B,2,FALSE) -> DuBois

Sheet Scenerio 4
G1: Scenerio 4 | I1: Channel:
A2: People | C2: altoona | D2: Location 1 | E2: Location 2 | F2: Location 3 | G2: Location 4 | H2: Location 5 | I2: Location 6 | J2: Location 7 | K2: Location 8 | L2: Location 9 | M2: Location 10
A3: a | C3: =COUNTIF(D3:M3, "altoona") -> 0 | D3: =VLOOKUP('Formula Workbook'!AG2,Cities!$A:$B,2,FALSE) -> Corry | E3: =VLOOKUP('Formula Workbook'!AH2,Cities!$A:$B,2,FALSE) -> Greensburg | F3: =VLOOKUP('Formula Workbook'!AI2,Cities!$A:$B,2,FALSE) -> Jeannette | G3: =VLOOKUP('Formula Workbook'!AJ2,Cities!$A:$B,2,FALSE) -> Franklin | H3: =VLOOKUP('Formula Workbook'!AK2,Cities!$A:$B,2,FALSE) -> Connellsville | I3: =VLOOKUP('Formula Workbook'!AL2,Cities!$A:$B,2,FALSE) -> Chester | J3: =VLOOKUP('Formula Workbook'!AM2,Cities!$A:$B,2,FALSE) -> Wilkes-Barre | K3: =VLOOKUP('Formula Workbook'!AN2,Cities!$A:$B,2,FALSE) -> Pittsburgh | ... M3: =VLOOKUP('Formula Workbook'!AP2,Cities!$A:$B,2,FALSE) -> Hazleton
A4: b | B4: Shigella | C4: =COUNTIF(D4:M4, "altoona") -> 1 | D4: =VLOOKUP('Formula Workbook'!AG3,Cities!$A:$B,2,FALSE) -> Bethlehem | E4: =VLOOKUP('Formula Workbook'!AH3,Cities!$A:$B,2,FALSE) -> Philadelphia | F4: =VLOOKUP('Formula Workbook'!AI3,Cities!$A:$B,2,FALSE) -> Easton | G4: =VLOOKUP('Formula Workbook'!AJ3,Cities!$A:$B,2,FALSE) -> Jeannette | H4: =VLOOKUP('Formula Workbook'!AK3,Cities!$A:$B,2,FALSE) -> Duquesne | I4: =VLOOKUP('Formula Workbook'!AL3,Cities!$A:$B,2,FALSE) -> Philadelphia | J4: =VLOOKUP('Formula Workbook'!AM3,Cities!$A:$B,2,FALSE) -> Jeannette | K4: =VLOOKUP('Formula Workbook'!AN3,Cities!$A:$B,2,FALSE) -> Altoona | ... M4: =VLOOKUP('Formula Workbook'!AP3,Cities!$A:$B,2,FALSE) -> Butler
